Workbook

Sheet Read Me
B2: KiranaOS — Revenue Model by Shop Type
B3: Built 22 August 2026 · three-year plan, base and aggressive cases · all figures in INR
B5: How to use this workbook
B6: Every cell in blue is an input you can change. Everything in black is a formula that recalculates from those inputs. Yellow-filled cells are the assumptions that move the answer most — change those first. Nothing here is hardcoded output: if you disagree with a churn rate or a hiring plan, edit it and the whole model follows.
B8: The sheets, in the order they were built
B9: Assumptions — global levers: plan mix, margins, sales productivity, cost per head.
B10: Market Sizing — outlets per trade in India, how many are realistically software buyers, and how confident that number is.
B11: Unit Economics — blended price, churn, CAC, LTV and payback for each of the eleven trades. This is the sheet that decides strategy.
B12: Vertical Ranking — a weighted score per trade. Weights are editable; the ranking re-sorts itself.
B13: Base Case — twelve quarters, founder-led, no outside money.
B14: Aggressive Case — twelve quarters assuming a raise at the end of year one.
B15: Summary — the two cases side by side.
... B28: This is a planning model, not a forecast, and not financial advice. Its purpose is to make the assumptions arguable.

Sheet Assumptions
B2: Assumptions
B3: Blue = input you can change. Yellow = the ones that matter most.
B5: Plan mix — what share of shops buy each tier
B6: Starter share | C6: 0.5 | D6: Most shops start on the entry tier.
B7: Growth share | C7: 0.4 | D7: Staff accounts, multi-device, advanced pricing.
B8: Business share | C8: 0.1 | D8: Multi-counter and multi-store.
B9: Check — must equal 100% | C9: =SUM(C6:C8) -> 1
B11: Pricing and margin
B12: Launch service fee (one-time) | C12: 4999 | D12: Install, catalogue entry, training, first-year support. Services revenue.
B13: Subscription gross margin | C13: 0.85 | D13: Hosting plus routine support.
B14: Launch service gross margin | C14: 0.4 | D14: Carries a person's day and travel. Deliberately low.
B15: Infrastructure cost per shop per year | C15: 150 | D15: Database, storage, backups, SMS/WhatsApp allowance.
B17: Sales productivity and cost
B18: Closes per rep per quarter | C18: 24 | D18: 8 a month. Achievable in clustered markets; optimistic for scattered kirana.
B19: Rep loaded cost per month | C19: 40000 | D19: Salary, incentive, travel.
B20: Base CAC per shop | C20: 5000 | D20: Sales cost per closed shop before the per-trade difficulty multiplier.
B21: Support staff cost per month | C21: 25000
B22: Active shops per support staff | C22: 250 | D22: Drives support hiring automatically.
B23: Engineer loaded cost per month | C23: 120000 | D23: Market rate for a hired engineer.
B24: Other opex as % of revenue | C24: 0.15 | D24: Office, tools, compliance, marketing, payment fees.
B26: Founder cost
B27: Founders in the engineering count | C27: 1 | D27: You. Counted inside the Engineers row on each case sheet.
B28: Founder draw per month | C28: 40000 | D28: What you actually take out, not what you are worth. Set to 0 to see pure cash cost.
B30: Engineering cost = (engineers − founders) × market rate + founders × founder draw. Set the founder draw to a market salary to see fully-loaded economics including your own opportunity cost.
B32: Everything else in this workbook is derived from the cells above, from the pricing table on Unit Economics, or from the hiring plan on each case sheet.

Sheet Market Sizing
B2: Market Sizing by Shop Type
B3: Outlet counts are for India. Read these to rank trades against each other — not as a revenue ceiling. Sales capacity binds long before any of these numbers do.
B5: Shop type | C5: Outlets in India | D5: Confidence | E5: Software-ready % | F5: Addressable shops | G5: Market value (₹ Cr) | H5: Basis for the outlet count
B6: Restaurant / café | C6: 2300000 | D6: Medium | E6: 0.25 | F6: =C6*E6 -> 575000 | G6: =F6*'Unit Economics'!F6/10000000 -> 459.9425 | H6: NRAI IFSR 2024 direction; Mumbai alone 141,456 outlets. National figure is an industry estimate.
B7: Pharmacy / medical | C7: 1200000 | D7: High | E7: 0.45 | F7: =C7*E7 -> 540000 | G7: =F7*'Unit Economics'!F7/10000000 -> 372.546 | H7: AIOCD: ~12 lakh retail pharmacies (May 2026 strike coverage).
B8: Auto parts / hardware | C8: 500000 | D8: Low | E8: 0.12 | F8: =C8*E8 -> 60000 | G8: =F8*'Unit Economics'!F8/10000000 -> 35.394 | H8: Estimate. No reliable public census; clustered in known auto markets.
B9: Electronics / mobiles | C9: 450000 | D9: Low | E9: 0.2 | F9: =C9*E9 -> 90000 | G9: =F9*'Unit Economics'!F9/10000000 -> 53.091 | H9: Estimate. AIMRA represents ~1.5 lakh mobile retailers; broader electronics adds to that.
B10: Clothing / fashion | C10: 1600000 | D10: Low | E10: 0.15 | F10: =C10*E10 -> 240000 | G10: =F10*'Unit Economics'!F10/10000000 -> 123.576 | H10: Estimate. Apparel is the largest non-food retail category by outlet count.
B11: Footwear | C11: 400000 | D11: Low | E11: 0.12 | F11: =C11*E11 -> 48000 | G11: =F11*'Unit Economics'!F11/10000000 -> 24.7152 | H11: Estimate.
B12: Cosmetics / beauty | C12: 350000 | D12: Low | E12: 0.12 | F12: =C12*E12 -> 42000 | G12: =F12*'Unit Economics'!F12/10000000 -> 21.6258 | H12: Estimate.
B13: Furniture / home | C13: 300000 | D13: Low | E13: 0.1 | F13: =C13*E13 -> 30000 | G13: =F13*'Unit Economics'!F13/10000000 -> 17.697 | H13: Estimate.
B14: Stationery / books | C14: 350000 | D14: Low | E14: 0.08 | F14: =C14*E14 -> 28000 | G14: =F14*'Unit Economics'!F14/10000000 -> 11.6172 | H14: Estimate. Demand is strongly seasonal around school-list season.
B15: Kirana / general store | C15: 13000000 | D15: High | E15: 0.08 | F15: =C15*E15 -> 1040000 | G15: =F15*'Unit Economics'!F15/10000000 -> 431.496 | H15: Widely cited ~13 million kirana stores (Invest India, Cornell, industry press).
B16: Other / custom retail | C16: 1000000 | D16: Low | E16: 0.08 | F16: =C16*E16 -> 80000 | G16: =F16*'Unit Economics'!F16/10000000 -> 33.192 | H16: Catch-all for trades served by the custom pack.
B17: Total | C17: =SUM(C6:C16) -> 21450000 | F17: =SUM(F6:F16) -> 2773000 | G17: =SUM(G6:G16) -> 1584.8927
B19: “Software-ready %” is the share of shops in that trade who already pay for billing software or would if asked. It is an estimate in every row — change it and the addressable numbers follow.
B20: Market value is addressable shops × your own blended annual price for that trade. It is the size of the prize if you took the entire addressable market, which you will not.

Sheet Unit Economics
B2: Unit Economics by Shop Type
B3: Prices are your own, from docs/PRICING_BUNDLE.md. Churn and CAC difficulty are estimates — they are the two numbers most worth arguing about.
B5: Shop type | C5: Starter | D5: Growth | E5: Business | F5: Blended ARPU | G5: Annual churn | H5: CAC difficulty | I5: CAC | J5: LTV | K5: LTV / CAC | L5: CAC payback (months) | M5: Read
B6: Restaurant / café | C6: 5999 | D6: 8999 | E6: 13999 | F6: =C6*Assumptions!$C$6+D6*Assumptions!$C$7+E6*Assumptions!$C$8 -> 7999 | G6: 0.2 | H6: 1 | I6: =Assumptions!$C$20*H6 -> 5000 | J6: =IF(G6=0,0,F6*Assumptions!$C$13/G6) -> 33995.75 | K6: =IF(I6=0,0,J6/I6) -> 6.79915 | L6: =IF(F6=0,0,I6/(F6*Assumptions!$C$13/12)) -> 8.8246325 | M6: Petpooja charges ₹36k–₹1.44L/yr. You charge ₹8,999. Product is already forked and complete.
B7: Pharmacy / medical | C7: 4999 | D7: 7999 | E7: 11999 | F7: =C7*Assumptions!$C$6+D7*Assumptions!$C$7+E7*Assumptions!$C$8 -> 6899 | G7: 0.12 | H7: 1.1 | I7: =Assumptions!$C$20*H7 -> 5500 | J7: =IF(G7=0,0,F7*Assumptions!$C$13/G7) -> 48867.917 | K7: =IF(I7=0,0,J7/I7) -> 8.8850758 | L7: =IF(F7=0,0,I7/(F7*Assumptions!$C$13/12)) -> 11.254828 | M7: Batch, expiry and Schedule-H are legally required, not nice-to-have. Marg is entrenched but hated. Best retention of any trade.
B8: Auto parts / hardware | C8: 3999 | D8: 6999 | E8: 10999 | F8: =C8*Assumptions!$C$6+D8*Assumptions!$C$7+E8*Assumptions!$C$8 -> 5899 | G8: 0.15 | H8: 1 | I8: =Assumptions!$C$20*H8 -> 5000 | J8: =IF(G8=0,0,F8*Assumptions!$C$13/G8) -> 33427.667 | K8: =IF(I8=0,0,J8/I8) -> 6.6855333 | L8: =IF(F8=0,0,I8/(F8*Assumptions!$C$13/12)) -> 11.966136 | M8: The most underrated line. Fitment lookup is a genuinely hard problem you already solved, and almost nobody serves this trade well.
B9: Electronics / mobiles | C9: 3999 | D9: 6999 | E9: 10999 | F9: =C9*Assumptions!$C$6+D9*Assumptions!$C$7+E9*Assumptions!$C$8 -> 5899 | G9: 0.2 | H9: 1 | I9: =Assumptions!$C$20*H9 -> 5000 | J9: =IF(G9=0,0,F9*Assumptions!$C$13/G9) -> 25070.75 | K9: =IF(I9=0,0,J9/I9) -> 5.01415 | L9: =IF(F9=0,0,I9/(F9*Assumptions!$C$13/12)) -> 11.966136 | M9: Serial/IMEI tracking built. AIMRA gives you a channel. Margin pressure makes shops price-sensitive.
B10: Clothing / fashion | C10: 3499 | D10: 5999 | E10: 9999 | F10: =C10*Assumptions!$C$6+D10*Assumptions!$C$7+E10*Assumptions!$C$8 -> 5149 | G10: 0.2 | H10: 1.2 | I10: =Assumptions!$C$20*H10 -> 6000 | J10: =IF(G10=0,0,F10*Assumptions!$C$13/G10) -> 21883.25 | K10: =IF(I10=0,0,J10/I10) -> 3.6472083 | L10: =IF(F10=0,0,I10/(F10*Assumptions!$C$13/12)) -> 16.450939 | M10: Size-run support built. Crowded with Ginesys, GoFrugal and others at higher price points.
B11: Footwear | C11: 3499 | D11: 5999 | E11: 9999 | F11: =C11*Assumptions!$C$6+D11*Assumptions!$C$7+E11*Assumptions!$C$8 -> 5149 | G11: 0.22 | H11: 1.2 | I11: =Assumptions!$C$20*H11 -> 6000 | J11: =IF(G11=0,0,F11*Assumptions!$C$13/G11) -> 19893.864 | K11: =IF(I11=0,0,J11/I11) -> 3.3156439 | L11: =IF(F11=0,0,I11/(F11*Assumptions!$C$13/12)) -> 16.450939 | M11: Same engine as clothing, smaller market. Take it as a free adjacency, not a campaign.
B12: Cosmetics / beauty | C12: 3499 | D12: 5999 | E12: 9999 | F12: =C12*Assumptions!$C$6+D12*Assumptions!$C$7+E12*Assumptions!$C$8 -> 5149 | G12: 0.22 | H12: 1.2 | I12: =Assumptions!$C$20*H12 -> 6000 | J12: =IF(G12=0,0,F12*Assumptions!$C$13/G12) -> 19893.864 | K12: =IF(I12=0,0,J12/I12) -> 3.3156439 | L12: =IF(F12=0,0,I12/(F12*Assumptions!$C$13/12)) -> 16.450939 | M12: Tester and batch tracking built. Small, fragmented, no association to sell through.
B13: Furniture / home | C13: 3999 | D13: 6999 | E13: 10999 | F13: =C13*Assumptions!$C$6+D13*Assumptions!$C$7+E13*Assumptions!$C$8 -> 5899 | G13: 0.18 | H13: 1.3 | I13: =Assumptions!$C$20*H13 -> 6500 | J13: =IF(G13=0,0,F13*Assumptions!$C$13/G13) -> 27856.389 | K13: =IF(I13=0,0,J13/I13) -> 4.2855983 | L13: =IF(F13=0,0,I13/(F13*Assumptions!$C$13/12)) -> 15.555977 | M13: Custom-order flow built. Low outlet count, long sales cycle, but sticky once installed.
B14: Stationery / books | C14: 2499 | D14: 4999 | E14: 8999 | F14: =C14*Assumptions!$C$6+D14*Assumptions!$C$7+E14*Assumptions!$C$8 -> 4149 | G14: 0.25 | H14: 1.3 | I14: =Assumptions!$C$20*H14 -> 6500 | J14: =IF(G14=0,0,F14*Assumptions!$C$13/G14) -> 14106.6 | K14: =IF(I14=0,0,J14/I14) -> 2.1702462 | L14: =IF(F14=0,0,I14/(F14*Assumptions!$C$13/12)) -> 22.117307 | M14: Book-list feature built. Revenue is one seasonal spike a year, which makes churn look worse than it is.
B15: Kirana / general store | C15: 2499 | D15: 4999 | E15: 8999 | F15: =C15*Assumptions!$C$6+D15*Assumptions!$C$7+E15*Assumptions!$C$8 -> 4149 | G15: 0.3 | H15: 1.4 | I15: =Assumptions!$C$20*H15 -> 7000 | J15: =IF(G15=0,0,F15*Assumptions!$C$13/G15) -> 11755.5 | K15: =IF(I15=0,0,J15/I15) -> 1.6793571 | L15: =IF(F15=0,0,I15/(F15*Assumptions!$C$13/12)) -> 23.818638 | M15: Your namesake and your weakest commercial position. Vyapar is free, the market is 13 million shops with no channel, and willingness to pay is the lowest of any trade.
B16: Other / custom retail | C16: 2499 | D16: 4999 | E16: 8999 | F16: =C16*Assumptions!$C$6+D16*Assumptions!$C$7+E16*Assumptions!$C$8 -> 4149 | G16: 0.28 | H16: 1.4 | I16: =Assumptions!$C$20*H16 -> 7000 | J16: =IF(G16=0,0,F16*Assumptions!$C$13/G16) -> 12595.179 | K16: =IF(I16=0,0,J16/I16) -> 1.7993112 | L16: =IF(F16=0,0,I16/(F16*Assumptions!$C$13/12)) -> 23.818638 | M16: Fallback pack. Accept inbound, never campaign into it.
B18: LTV = blended ARPU × subscription gross margin ÷ annual churn. CAC = base CAC × the trade's difficulty multiplier. Below 3.0× LTV/CAC, paid field acquisition does not pay for itself.
B19: The ₹4,999 launch service is excluded from LTV on purpose — it roughly covers its own delivery cost and should not be used to make acquisition look profitable.

Sheet Vertical Ranking
B2: Which Trades to Attack, in Order
B3: Scores are 1 (worst) to 5 (best). Weights on row 5 are inputs — change what you care about and the ranking follows.
B5: Weights → | C5: 0.25 | D5: 0.2 | E5: 0.15 | F5: 0.15 | G5: 0.15 | H5: 0.1 | I5: =SUM(C5:H5) -> 1 | J5: ← must be 100%
B7: Shop type | C7: Price headroom | D7: Pain intensity | E7: Product readiness | F7: Competitive whitespace | G7: Reach- ability | H7: Retention | I7: Weighted score | J7: Rank | K7: Why
B8: Restaurant / café | C8: 5 | D8: 5 | E8: 5 | F8: 3 | G8: 4 | H8: 3 | I8: =SUMPRODUCT(C8:H8,$C$5:$H$5) -> 4.35 | J8: =RANK(I8,$I$8:$I$18) -> 1 | K8: Petpooja charges ₹36k–₹1.44L/yr. You charge ₹8,999. Product is already forked and complete.
B9: Pharmacy / medical | C9: 4 | D9: 5 | E9: 4 | F9: 2 | G9: 4 | H9: 5 | I9: =SUMPRODUCT(C9:H9,$C$5:$H$5) -> 4 | J9: =RANK(I9,$I$8:$I$18) -> 3 | K9: Batch, expiry and Schedule-H are legally required, not nice-to-have. Marg is entrenched but hated. Best retention of any trade.
B10: Auto parts / hardware | C10: 4 | D10: 5 | E10: 4 | F10: 4 | G10: 4 | H10: 4 | I10: =SUMPRODUCT(C10:H10,$C$5:$H$5) -> 4.2 | J10: =RANK(I10,$I$8:$I$18) -> 2 | K10: The most underrated line. Fitment lookup is a genuinely hard problem you already solved, and almost nobody serves this trade well.
B11: Electronics / mobiles | C11: 3 | D11: 4 | E11: 4 | F11: 3 | G11: 4 | H11: 3 | I11: =SUMPRODUCT(C11:H11,$C$5:$H$5) -> 3.5 | J11: =RANK(I11,$I$8:$I$18) -> 4 | K11: Serial/IMEI tracking built. AIMRA gives you a channel. Margin pressure makes shops price-sensitive.
B12: Clothing / fashion | C12: 3 | D12: 4 | E12: 4 | F12: 3 | G12: 3 | H12: 3 | I12: =SUMPRODUCT(C12:H12,$C$5:$H$5) -> 3.35 | J12: =RANK(I12,$I$8:$I$18) -> 5 | K12: Size-run support built. Crowded with Ginesys, GoFrugal and others at higher price points.
B13: Footwear | C13: 3 | D13: 3 | E13: 4 | F13: 3 | G13: 3 | H13: 3 | I13: =SUMPRODUCT(C13:H13,$C$5:$H$5) -> 3.15 | J13: =RANK(I13,$I$8:$I$18) -> 6 | K13: Same engine as clothing, smaller market. Take it as a free adjacency, not a campaign.
B14: Cosmetics / beauty | C14: 3 | D14: 3 | E14: 3 | F14: 3 | G14: 3 | H14: 3 | I14: =SUMPRODUCT(C14:H14,$C$5:$H$5) -> 3 | J14: =RANK(I14,$I$8:$I$18) -> 8 | K14: Tester and batch tracking built. Small, fragmented, no association to sell through.
B15: Furniture / home | C15: 3 | D15: 3 | E15: 3 | F15: 4 | G15: 2 | H15: 4 | I15: =SUMPRODUCT(C15:H15,$C$5:$H$5) -> 3.1 | J15: =RANK(I15,$I$8:$I$18) -> 7 | K15: Custom-order flow built. Low outlet count, long sales cycle, but sticky once installed.
B16: Stationery / books | C16: 2 | D16: 2 | E16: 3 | F16: 3 | G16: 3 | H16: 3 | I16: =SUMPRODUCT(C16:H16,$C$5:$H$5) -> 2.55 | J16: =RANK(I16,$I$8:$I$18) -> 9 | K16: Book-list feature built. Revenue is one seasonal spike a year, which makes churn look worse than it is.
B17: Kirana / general store | C17: 1 | D17: 2 | E17: 5 | F17: 1 | G17: 2 | H17: 2 | I17: =SUMPRODUCT(C17:H17,$C$5:$H$5) -> 2.05 | J17: =RANK(I17,$I$8:$I$18) -> 11 | K17: Your namesake and your weakest commercial position. Vyapar is free, the market is 13 million shops with no channel, and willingness to pay is the lowest of any trade.
B18: Other / custom retail | C18: 2 | D18: 2 | E18: 3 | F18: 2 | G18: 2 | H18: 2 | I18: =SUMPRODUCT(C18:H18,$C$5:$H$5) -> 2.15 | J18: =RANK(I18,$I$8:$I$18) -> 10 | K18: Fallback pack. Accept inbound, never campaign into it.
B20: Price headroom = how far your price sits below the incumbent's. Pain intensity = how badly the shop needs software at all. Product readiness = how much of that trade you have already built and tested. Competitive whitespace = how poorly the trade is currently served. Reachability = whether shops cluster geographically or have an association you can sell through. Retention = how likely they are to still be paying in three years.

Sheet Base Case
B2: Base Case
B3: Founder-led, no outside money. One rep by the end of year one, five by the end of year three. Restaurant-first, then pharmacy and auto parts.
B5: Quarter | C5: Q4 2026 | D5: Q1 2027 | E5: Q2 2027 | F5: Q3 2027 | G5: Q4 2027 | H5: Q1 2028 | I5: Q2 2028 | J5: Q3 2028 | K5: Q4 2028 | L5: Q1 2029 | M5: Q2 2029 | N5: Q3 2029
B6: Plan year | C6: 1 | D6: 1 | E6: 1 | F6: 1 | G6: 2 | H6: 2 | I6: 2 | J6: 2 | K6: 3 | L6: 3 | M6: 3 | N6: 3
B8: Hiring plan — edit these
B9: Sales reps (avg in quarter) | C9: 0.5 | D9: 1 | E9: 1 | F9: 1.5 | G9: 2 | H9: 2 | I9: 3 | J9: 3 | K9: 4 | L9: 4 | M9: 5 | N9: 5
B10: Engineers (incl. you) | C10: 1 | D10: 1 | E10: 1 | F10: 1 | G10: 1 | H10: 1 | I10: 1.5 | J10: 1.5 | K10: 2 | L10: 2 | M10: 2 | N10: 2
B11: Closes per rep per quarter | C11: =Assumptions!$C$18 -> 24 | D11: =Assumptions!$C$18 -> 24 | E11: =Assumptions!$C$18 -> 24 | F11: =Assumptions!$C$18 -> 24 | G11: =Assumptions!$C$18 -> 24 | H11: =Assumptions!$C$18 -> 24 | I11: =Assumptions!$C$18 -> 24 | J11: =Assumptions!$C$18 -> 24 | ... N11: =Assumptions!$C$18 -> 24
B12: Gross new shops | C12: =ROUND(C9*C11,0) -> 12 | D12: =ROUND(D9*D11,0) -> 24 | E12: =ROUND(E9*E11,0) -> 24 | F12: =ROUND(F9*F11,0) -> 36 | G12: =ROUND(G9*G11,0) -> 48 | H12: =ROUND(H9*H11,0) -> 48 | I12: =ROUND(I9*I11,0) -> 72 | J12: =ROUND(J9*J11,0) -> 72 | ... N12: =ROUND(N9*N11,0) -> 120
B14: Share of new shops by trade — edit these
C15: Year 1 | D15: Year 2 | E15: Year 3
B16: Restaurant / café | C16: 0.7 | D16: 0.5 | E16: 0.4
B17: Pharmacy / medical | C17: 0.1 | D17: 0.2 | E17: 0.2
B18: Auto parts / hardware | C18: 0.1 | D18: 0.15 | E18: 0.15
B19: Electronics / mobiles | C19: 0 | D19: 0.05 | E19: 0.08
B20: Clothing / fashion | C20: 0 | D20: 0.05 | E20: 0.07
B21: Footwear | C21: 0 | D21: 0 | E21: 0.03
B22: Cosmetics / beauty | C22: 0 | D22: 0 | E22: 0.02
B23: Furniture / home | C23: 0 | D23: 0 | E23: 0.02
B24: Stationery / books | C24: 0 | D24: 0 | E24: 0
B25: Kirana / general store | C25: 0.05 | D25: 0.05 | E25: 0.03
B26: Other / custom retail | C26: 0.05 | D26: 0 | E26: 0
B27: Check — must be 100% | C27: =SUM(C16:C26) -> 1 | D27: =SUM(D16:D26) -> 1 | E27: =SUM(E16:E26) -> 1
B29: New shops signed, by trade
B30: Restaurant / café | C30: =ROUND(C$12*INDEX($C16:$E16,C$6),0) -> 8 | D30: =ROUND(D$12*INDEX($C16:$E16,D$6),0) -> 17 | E30: =ROUND(E$12*INDEX($C16:$E16,E$6),0) -> 17 | F30: =ROUND(F$12*INDEX($C16:$E16,F$6),0) -> 25 | G30: =ROUND(G$12*INDEX($C16:$E16,G$6),0) -> 24 | H30: =ROUND(H$12*INDEX($C16:$E16,H$6),0) -> 24 | I30: =ROUND(I$12*INDEX($C16:$E16,I$6),0) -> 36 | J30: =ROUND(J$12*INDEX($C16:$E16,J$6),0) -> 36 | ... N30: =ROUND(N$12*INDEX($C16:$E16,N$6),0) -> 48
B31: Pharmacy / medical | C31: =ROUND(C$12*INDEX($C17:$E17,C$6),0) -> 1 | D31: =ROUND(D$12*INDEX($C17:$E17,D$6),0) -> 2 | E31: =ROUND(E$12*INDEX($C17:$E17,E$6),0) -> 2 | F31: =ROUND(F$12*INDEX($C17:$E17,F$6),0) -> 4 | G31: =ROUND(G$12*INDEX($C17:$E17,G$6),0) -> 10 | H31: =ROUND(H$12*INDEX($C17:$E17,H$6),0) -> 10 | I31: =ROUND(I$12*INDEX($C17:$E17,I$6),0) -> 14 | J31: =ROUND(J$12*INDEX($C17:$E17,J$6),0) -> 14 | ... N31: =ROUND(N$12*INDEX($C17:$E17,N$6),0) -> 24
B32: Auto parts / hardware | C32: =ROUND(C$12*INDEX($C18:$E18,C$6),0) -> 1 | D32: =ROUND(D$12*INDEX($C18:$E18,D$6),0) -> 2 | E32: =ROUND(E$12*INDEX($C18:$E18,E$6),0) -> 2 | F32: =ROUND(F$12*INDEX($C18:$E18,F$6),0) -> 4 | G32: =ROUND(G$12*INDEX($C18:$E18,G$6),0) -> 7 | H32: =ROUND(H$12*INDEX($C18:$E18,H$6),0) -> 7 | I32: =ROUND(I$12*INDEX($C18:$E18,I$6),0) -> 11 | J32: =ROUND(J$12*INDEX($C18:$E18,J$6),0) -> 11 | ... N32: =ROUND(N$12*INDEX($C18:$E18,N$6),0) -> 18
B33: Electronics / mobiles | C33: =ROUND(C$12*INDEX($C19:$E19,C$6),0) -> 0 | D33: =ROUND(D$12*INDEX($C19:$E19,D$6),0) -> 0 | E33: =ROUND(E$12*INDEX($C19:$E19,E$6),0) -> 0 | F33: =ROUND(F$12*INDEX($C19:$E19,F$6),0) -> 0 | G33: =ROUND(G$12*INDEX($C19:$E19,G$6),0) -> 2 | H33: =ROUND(H$12*INDEX($C19:$E19,H$6),0) -> 2 | I33: =ROUND(I$12*INDEX($C19:$E19,I$6),0) -> 4 | J33: =ROUND(J$12*INDEX($C19:$E19,J$6),0) -> 4 | ... N33: =ROUND(N$12*INDEX($C19:$E19,N$6),0) -> 10
B34: Clothing / fashion | C34: =ROUND(C$12*INDEX($C20:$E20,C$6),0) -> 0 | D34: =ROUND(D$12*INDEX($C20:$E20,D$6),0) -> 0 | E34: =ROUND(E$12*INDEX($C20:$E20,E$6),0) -> 0 | F34: =ROUND(F$12*INDEX($C20:$E20,F$6),0) -> 0 | G34: =ROUND(G$12*INDEX($C20:$E20,G$6),0) -> 2 | H34: =ROUND(H$12*INDEX($C20:$E20,H$6),0) -> 2 | I34: =ROUND(I$12*INDEX($C20:$E20,I$6),0) -> 4 | J34: =ROUND(J$12*INDEX($C20:$E20,J$6),0) -> 4 | ... N34: =ROUND(N$12*INDEX($C20:$E20,N$6),0) -> 8
B35: Footwear | C35: =ROUND(C$12*INDEX($C21:$E21,C$6),0) -> 0 | D35: =ROUND(D$12*INDEX($C21:$E21,D$6),0) -> 0 | E35: =ROUND(E$12*INDEX($C21:$E21,E$6),0) -> 0 | F35: =ROUND(F$12*INDEX($C21:$E21,F$6),0) -> 0 | G35: =ROUND(G$12*INDEX($C21:$E21,G$6),0) -> 0 | H35: =ROUND(H$12*INDEX($C21:$E21,H$6),0) -> 0 | I35: =ROUND(I$12*INDEX($C21:$E21,I$6),0) -> 0 | J35: =ROUND(J$12*INDEX($C21:$E21,J$6),0) -> 0 | ... N35: =ROUND(N$12*INDEX($C21:$E21,N$6),0) -> 4
B36: Cosmetics / beauty | C36: =ROUND(C$12*INDEX($C22:$E22,C$6),0) -> 0 | D36: =ROUND(D$12*INDEX($C22:$E22,D$6),0) -> 0 | E36: =ROUND(E$12*INDEX($C22:$E22,E$6),0) -> 0 | F36: =ROUND(F$12*INDEX($C22:$E22,F$6),0) -> 0 | G36: =ROUND(G$12*INDEX($C22:$E22,G$6),0) -> 0 | H36: =ROUND(H$12*INDEX($C22:$E22,H$6),0) -> 0 | I36: =ROUND(I$12*INDEX($C22:$E22,I$6),0) -> 0 | J36: =ROUND(J$12*INDEX($C22:$E22,J$6),0) -> 0 | ... N36: =ROUND(N$12*INDEX($C22:$E22,N$6),0) -> 2
B37: Furniture / home | C37: =ROUND(C$12*INDEX($C23:$E23,C$6),0) -> 0 | D37: =ROUND(D$12*INDEX($C23:$E23,D$6),0) -> 0 | E37: =ROUND(E$12*INDEX($C23:$E23,E$6),0) -> 0 | F37: =ROUND(F$12*INDEX($C23:$E23,F$6),0) -> 0 | G37: =ROUND(G$12*INDEX($C23:$E23,G$6),0) -> 0 | H37: =ROUND(H$12*INDEX($C23:$E23,H$6),0) -> 0 | I37: =ROUND(I$12*INDEX($C23:$E23,I$6),0) -> 0 | J37: =ROUND(J$12*INDEX($C23:$E23,J$6),0) -> 0 | ... N37: =ROUND(N$12*INDEX($C23:$E23,N$6),0) -> 2
B38: Stationery / books | C38: =ROUND(C$12*INDEX($C24:$E24,C$6),0) -> 0 | D38: =ROUND(D$12*INDEX($C24:$E24,D$6),0) -> 0 | E38: =ROUND(E$12*INDEX($C24:$E24,E$6),0) -> 0 | F38: =ROUND(F$12*INDEX($C24:$E24,F$6),0) -> 0 | G38: =ROUND(G$12*INDEX($C24:$E24,G$6),0) -> 0 | H38: =ROUND(H$12*INDEX($C24:$E24,H$6),0) -> 0 | I38: =ROUND(I$12*INDEX($C24:$E24,I$6),0) -> 0 | J38: =ROUND(J$12*INDEX($C24:$E24,J$6),0) -> 0 | ... N38: =ROUND(N$12*INDEX($C24:$E24,N$6),0) -> 0
B39: Kirana / general store | C39: =ROUND(C$12*INDEX($C25:$E25,C$6),0) -> 1 | D39: =ROUND(D$12*INDEX($C25:$E25,D$6),0) -> 1 | E39: =ROUND(E$12*INDEX($C25:$E25,E$6),0) -> 1 | F39: =ROUND(F$12*INDEX($C25:$E25,F$6),0) -> 2 | G39: =ROUND(G$12*INDEX($C25:$E25,G$6),0) -> 2 | H39: =ROUND(H$12*INDEX($C25:$E25,H$6),0) -> 2 | I39: =ROUND(I$12*INDEX($C25:$E25,I$6),0) -> 4 | J39: =ROUND(J$12*INDEX($C25:$E25,J$6),0) -> 4 | ... N39: =ROUND(N$12*INDEX($C25:$E25,N$6),0) -> 4
B40: Other / custom retail | C40: =ROUND(C$12*INDEX($C26:$E26,C$6),0) -> 1 | D40: =ROUND(D$12*INDEX($C26:$E26,D$6),0) -> 1 | E40: =ROUND(E$12*INDEX($C26:$E26,E$6),0) -> 1 | F40: =ROUND(F$12*INDEX($C26:$E26,F$6),0) -> 2 | G40: =ROUND(G$12*INDEX($C26:$E26,G$6),0) -> 0 | H40: =ROUND(H$12*INDEX($C26:$E26,H$6),0) -> 0 | I40: =ROUND(I$12*INDEX($C26:$E26,I$6),0) -> 0 | J40: =ROUND(J$12*INDEX($C26:$E26,J$6),0) -> 0 | ... N40: =ROUND(N$12*INDEX($C26:$E26,N$6),0) -> 0
B43: Active paying shops at quarter end
B44: Restaurant / café | C44: =C30 -> 8 | D44: =ROUND(C44*(1-'Unit Economics'!$G6)^0.25+D30,0) -> 25 | E44: =ROUND(D44*(1-'Unit Economics'!$G6)^0.25+E30,0) -> 41 | F44: =ROUND(E44*(1-'Unit Economics'!$G6)^0.25+F30,0) -> 64 | G44: =ROUND(F44*(1-'Unit Economics'!$G6)^0.25+G30,0) -> 85 | H44: =ROUND(G44*(1-'Unit Economics'!$G6)^0.25+H30,0) -> 104 | I44: =ROUND(H44*(1-'Unit Economics'!$G6)^0.25+I30,0) -> 134 | J44: =ROUND(I44*(1-'Unit Economics'!$G6)^0.25+J30,0) -> 163 | K44: =ROUND(J44*(1-'Unit Economics'!$G6)^0.25+K30,0) -> 192 | ... N44: =ROUND(M44*(1-'Unit Economics'!$G6)^0.25+N30,0) -> 290
B45: Pharmacy / medical | C45: =C31 -> 1 | D45: =ROUND(C45*(1-'Unit Economics'!$G7)^0.25+D31,0) -> 3 | E45: =ROUND(D45*(1-'Unit Economics'!$G7)^0.25+E31,0) -> 5 | F45: =ROUND(E45*(1-'Unit Economics'!$G7)^0.25+F31,0) -> 9 | G45: =ROUND(F45*(1-'Unit Economics'!$G7)^0.25+G31,0) -> 19 | H45: =ROUND(G45*(1-'Unit Economics'!$G7)^0.25+H31,0) -> 28 | I45: =ROUND(H45*(1-'Unit Economics'!$G7)^0.25+I31,0) -> 41 | J45: =ROUND(I45*(1-'Unit Economics'!$G7)^0.25+J31,0) -> 54 | K45: =ROUND(J45*(1-'Unit Economics'!$G7)^0.25+K31,0) -> 71 | ... N45: =ROUND(M45*(1-'Unit Economics'!$G7)^0.25+N31,0) -> 130
B46: Auto parts / hardware | C46: =C32 -> 1 | D46: =ROUND(C46*(1-'Unit Economics'!$G8)^0.25+D32,0) -> 3 | E46: =ROUND(D46*(1-'Unit Economics'!$G8)^0.25+E32,0) -> 5 | F46: =ROUND(E46*(1-'Unit Economics'!$G8)^0.25+F32,0) -> 9 | G46: =ROUND(F46*(1-'Unit Economics'!$G8)^0.25+G32,0) -> 16 | H46: =ROUND(G46*(1-'Unit Economics'!$G8)^0.25+H32,0) -> 22 | I46: =ROUND(H46*(1-'Unit Economics'!$G8)^0.25+I32,0) -> 32 | J46: =ROUND(I46*(1-'Unit Economics'!$G8)^0.25+J32,0) -> 42 | K46: =ROUND(J46*(1-'Unit Economics'!$G8)^0.25+K32,0) -> 54 | ... N46: =ROUND(M46*(1-'Unit Economics'!$G8)^0.25+N32,0) -> 96
B47: Electronics / mobiles | C47: =C33 -> 0 | D47: =ROUND(C47*(1-'Unit Economics'!$G9)^0.25+D33,0) -> 0 | E47: =ROUND(D47*(1-'Unit Economics'!$G9)^0.25+E33,0) -> 0 | F47: =ROUND(E47*(1-'Unit Economics'!$G9)^0.25+F33,0) -> 0 | G47: =ROUND(F47*(1-'Unit Economics'!$G9)^0.25+G33,0) -> 2 | H47: =ROUND(G47*(1-'Unit Economics'!$G9)^0.25+H33,0) -> 4 | I47: =ROUND(H47*(1-'Unit Economics'!$G9)^0.25+I33,0) -> 8 | J47: =ROUND(I47*(1-'Unit Economics'!$G9)^0.25+J33,0) -> 12 | K47: =ROUND(J47*(1-'Unit Economics'!$G9)^0.25+K33,0) -> 19 | ... N47: =ROUND(M47*(1-'Unit Economics'!$G9)^0.25+N33,0) -> 43
...

Sheet Aggressive Case
B2: Aggressive Case
B3: Assumes a raise at the end of year one. Forty-two reps by the end of year three, broader trade coverage, materially higher burn.
B5: Quarter | C5: Q4 2026 | D5: Q1 2027 | E5: Q2 2027 | F5: Q3 2027 | G5: Q4 2027 | H5: Q1 2028 | I5: Q2 2028 | J5: Q3 2028 | K5: Q4 2028 | L5: Q1 2029 | M5: Q2 2029 | N5: Q3 2029
B6: Plan year | C6: 1 | D6: 1 | E6: 1 | F6: 1 | G6: 2 | H6: 2 | I6: 2 | J6: 2 | K6: 3 | L6: 3 | M6: 3 | N6: 3
B8: Hiring plan — edit these
B9: Sales reps (avg in quarter) | C9: 1 | D9: 2 | E9: 3 | F9: 5 | G9: 10 | H9: 14 | I9: 18 | J9: 22 | K9: 28 | L9: 32 | M9: 38 | N9: 42
B10: Engineers (incl. you) | C10: 1 | D10: 2 | E10: 2 | F10: 3 | G10: 4 | H10: 5 | I10: 6 | J10: 6 | K10: 7 | L10: 8 | M10: 8 | N10: 9
B11: Closes per rep per quarter | C11: =Assumptions!$C$18 -> 24 | D11: =Assumptions!$C$18 -> 24 | E11: =Assumptions!$C$18 -> 24 | F11: =Assumptions!$C$18 -> 24 | G11: =Assumptions!$C$18 -> 24 | H11: =Assumptions!$C$18 -> 24 | I11: =Assumptions!$C$18 -> 24 | J11: =Assumptions!$C$18 -> 24 | ... N11: =Assumptions!$C$18 -> 24
B12: Gross new shops | C12: =ROUND(C9*C11,0) -> 24 | D12: =ROUND(D9*D11,0) -> 48 | E12: =ROUND(E9*E11,0) -> 72 | F12: =ROUND(F9*F11,0) -> 120 | G12: =ROUND(G9*G11,0) -> 240 | H12: =ROUND(H9*H11,0) -> 336 | I12: =ROUND(I9*I11,0) -> 432 | J12: =ROUND(J9*J11,0) -> 528 | ... N12: =ROUND(N9*N11,0) -> 1008
B14: Share of new shops by trade — edit these
C15: Year 1 | D15: Year 2 | E15: Year 3
B16: Restaurant / café | C16: 0.6 | D16: 0.4 | E16: 0.32
B17: Pharmacy / medical | C17: 0.15 | D17: 0.2 | E17: 0.2
B18: Auto parts / hardware | C18: 0.15 | D18: 0.15 | E18: 0.14
B19: Electronics / mobiles | C19: 0 | D19: 0.08 | E19: 0.1
B20: Clothing / fashion | C20: 0 | D20: 0.08 | E20: 0.09
B21: Footwear | C21: 0 | D21: 0.03 | E21: 0.04
B22: Cosmetics / beauty | C22: 0 | D22: 0.02 | E22: 0.03
B23: Furniture / home | C23: 0 | D23: 0 | E23: 0.03
B24: Stationery / books | C24: 0 | D24: 0 | E24: 0.02
B25: Kirana / general store | C25: 0.05 | D25: 0.04 | E25: 0.03
B26: Other / custom retail | C26: 0.05 | D26: 0 | E26: 0
B27: Check — must be 100% | C27: =SUM(C16:C26) -> 1 | D27: =SUM(D16:D26) -> 1 | E27: =SUM(E16:E26) -> 1
B29: New shops signed, by trade
B30: Restaurant / café | C30: =ROUND(C$12*INDEX($C16:$E16,C$6),0) -> 14 | D30: =ROUND(D$12*INDEX($C16:$E16,D$6),0) -> 29 | E30: =ROUND(E$12*INDEX($C16:$E16,E$6),0) -> 43 | F30: =ROUND(F$12*INDEX($C16:$E16,F$6),0) -> 72 | G30: =ROUND(G$12*INDEX($C16:$E16,G$6),0) -> 96 | H30: =ROUND(H$12*INDEX($C16:$E16,H$6),0) -> 134 | I30: =ROUND(I$12*INDEX($C16:$E16,I$6),0) -> 173 | J30: =ROUND(J$12*INDEX($C16:$E16,J$6),0) -> 211 | ... N30: =ROUND(N$12*INDEX($C16:$E16,N$6),0) -> 323
B31: Pharmacy / medical | C31: =ROUND(C$12*INDEX($C17:$E17,C$6),0) -> 4 | D31: =ROUND(D$12*INDEX($C17:$E17,D$6),0) -> 7 | E31: =ROUND(E$12*INDEX($C17:$E17,E$6),0) -> 11 | F31: =ROUND(F$12*INDEX($C17:$E17,F$6),0) -> 18 | G31: =ROUND(G$12*INDEX($C17:$E17,G$6),0) -> 48 | H31: =ROUND(H$12*INDEX($C17:$E17,H$6),0) -> 67 | I31: =ROUND(I$12*INDEX($C17:$E17,I$6),0) -> 86 | J31: =ROUND(J$12*INDEX($C17:$E17,J$6),0) -> 106 | ... N31: =ROUND(N$12*INDEX($C17:$E17,N$6),0) -> 202
B32: Auto parts / hardware | C32: =ROUND(C$12*INDEX($C18:$E18,C$6),0) -> 4 | D32: =ROUND(D$12*INDEX($C18:$E18,D$6),0) -> 7 | E32: =ROUND(E$12*INDEX($C18:$E18,E$6),0) -> 11 | F32: =ROUND(F$12*INDEX($C18:$E18,F$6),0) -> 18 | G32: =ROUND(G$12*INDEX($C18:$E18,G$6),0) -> 36 | H32: =ROUND(H$12*INDEX($C18:$E18,H$6),0) -> 50 | I32: =ROUND(I$12*INDEX($C18:$E18,I$6),0) -> 65 | J32: =ROUND(J$12*INDEX($C18:$E18,J$6),0) -> 79 | ... N32: =ROUND(N$12*INDEX($C18:$E18,N$6),0) -> 141
B33: Electronics / mobiles | C33: =ROUND(C$12*INDEX($C19:$E19,C$6),0) -> 0 | D33: =ROUND(D$12*INDEX($C19:$E19,D$6),0) -> 0 | E33: =ROUND(E$12*INDEX($C19:$E19,E$6),0) -> 0 | F33: =ROUND(F$12*INDEX($C19:$E19,F$6),0) -> 0 | G33: =ROUND(G$12*INDEX($C19:$E19,G$6),0) -> 19 | H33: =ROUND(H$12*INDEX($C19:$E19,H$6),0) -> 27 | I33: =ROUND(I$12*INDEX($C19:$E19,I$6),0) -> 35 | J33: =ROUND(J$12*INDEX($C19:$E19,J$6),0) -> 42 | ... N33: =ROUND(N$12*INDEX($C19:$E19,N$6),0) -> 101
B34: Clothing / fashion | C34: =ROUND(C$12*INDEX($C20:$E20,C$6),0) -> 0 | D34: =ROUND(D$12*INDEX($C20:$E20,D$6),0) -> 0 | E34: =ROUND(E$12*INDEX($C20:$E20,E$6),0) -> 0 | F34: =ROUND(F$12*INDEX($C20:$E20,F$6),0) -> 0 | G34: =ROUND(G$12*INDEX($C20:$E20,G$6),0) -> 19 | H34: =ROUND(H$12*INDEX($C20:$E20,H$6),0) -> 27 | I34: =ROUND(I$12*INDEX($C20:$E20,I$6),0) -> 35 | J34: =ROUND(J$12*INDEX($C20:$E20,J$6),0) -> 42 | ... N34: =ROUND(N$12*INDEX($C20:$E20,N$6),0) -> 91
B35: Footwear | C35: =ROUND(C$12*INDEX($C21:$E21,C$6),0) -> 0 | D35: =ROUND(D$12*INDEX($C21:$E21,D$6),0) -> 0 | E35: =ROUND(E$12*INDEX($C21:$E21,E$6),0) -> 0 | F35: =ROUND(F$12*INDEX($C21:$E21,F$6),0) -> 0 | G35: =ROUND(G$12*INDEX($C21:$E21,G$6),0) -> 7 | H35: =ROUND(H$12*INDEX($C21:$E21,H$6),0) -> 10 | I35: =ROUND(I$12*INDEX($C21:$E21,I$6),0) -> 13 | J35: =ROUND(J$12*INDEX($C21:$E21,J$6),0) -> 16 | ... N35: =ROUND(N$12*INDEX($C21:$E21,N$6),0) -> 40
B36: Cosmetics / beauty | C36: =ROUND(C$12*INDEX($C22:$E22,C$6),0) -> 0 | D36: =ROUND(D$12*INDEX($C22:$E22,D$6),0) -> 0 | E36: =ROUND(E$12*INDEX($C22:$E22,E$6),0) -> 0 | F36: =ROUND(F$12*INDEX($C22:$E22,F$6),0) -> 0 | G36: =ROUND(G$12*INDEX($C22:$E22,G$6),0) -> 5 | H36: =ROUND(H$12*INDEX($C22:$E22,H$6),0) -> 7 | I36: =ROUND(I$12*INDEX($C22:$E22,I$6),0) -> 9 | J36: =ROUND(J$12*INDEX($C22:$E22,J$6),0) -> 11 | ... N36: =ROUND(N$12*INDEX($C22:$E22,N$6),0) -> 30
B37: Furniture / home | C37: =ROUND(C$12*INDEX($C23:$E23,C$6),0) -> 0 | D37: =ROUND(D$12*INDEX($C23:$E23,D$6),0) -> 0 | E37: =ROUND(E$12*INDEX($C23:$E23,E$6),0) -> 0 | F37: =ROUND(F$12*INDEX($C23:$E23,F$6),0) -> 0 | G37: =ROUND(G$12*INDEX($C23:$E23,G$6),0) -> 0 | H37: =ROUND(H$12*INDEX($C23:$E23,H$6),0) -> 0 | I37: =ROUND(I$12*INDEX($C23:$E23,I$6),0) -> 0 | J37: =ROUND(J$12*INDEX($C23:$E23,J$6),0) -> 0 | ... N37: =ROUND(N$12*INDEX($C23:$E23,N$6),0) -> 30
B38: Stationery / books | C38: =ROUND(C$12*INDEX($C24:$E24,C$6),0) -> 0 | D38: =ROUND(D$12*INDEX($C24:$E24,D$6),0) -> 0 | E38: =ROUND(E$12*INDEX($C24:$E24,E$6),0) -> 0 | F38: =ROUND(F$12*INDEX($C24:$E24,F$6),0) -> 0 | G38: =ROUND(G$12*INDEX($C24:$E24,G$6),0) -> 0 | H38: =ROUND(H$12*INDEX($C24:$E24,H$6),0) -> 0 | I38: =ROUND(I$12*INDEX($C24:$E24,I$6),0) -> 0 | J38: =ROUND(J$12*INDEX($C24:$E24,J$6),0) -> 0 | ... N38: =ROUND(N$12*INDEX($C24:$E24,N$6),0) -> 20
B39: Kirana / general store | C39: =ROUND(C$12*INDEX($C25:$E25,C$6),0) -> 1 | D39: =ROUND(D$12*INDEX($C25:$E25,D$6),0) -> 2 | E39: =ROUND(E$12*INDEX($C25:$E25,E$6),0) -> 4 | F39: =ROUND(F$12*INDEX($C25:$E25,F$6),0) -> 6 | G39: =ROUND(G$12*INDEX($C25:$E25,G$6),0) -> 10 | H39: =ROUND(H$12*INDEX($C25:$E25,H$6),0) -> 13 | I39: =ROUND(I$12*INDEX($C25:$E25,I$6),0) -> 17 | J39: =ROUND(J$12*INDEX($C25:$E25,J$6),0) -> 21 | ... N39: =ROUND(N$12*INDEX($C25:$E25,N$6),0) -> 30
B40: Other / custom retail | C40: =ROUND(C$12*INDEX($C26:$E26,C$6),0) -> 1 | D40: =ROUND(D$12*INDEX($C26:$E26,D$6),0) -> 2 | E40: =ROUND(E$12*INDEX($C26:$E26,E$6),0) -> 4 | F40: =ROUND(F$12*INDEX($C26:$E26,F$6),0) -> 6 | G40: =ROUND(G$12*INDEX($C26:$E26,G$6),0) -> 0 | H40: =ROUND(H$12*INDEX($C26:$E26,H$6),0) -> 0 | I40: =ROUND(I$12*INDEX($C26:$E26,I$6),0) -> 0 | J40: =ROUND(J$12*INDEX($C26:$E26,J$6),0) -> 0 | ... N40: =ROUND(N$12*INDEX($C26:$E26,N$6),0) -> 0
B43: Active paying shops at quarter end
B44: Restaurant / café | C44: =C30 -> 14 | D44: =ROUND(C44*(1-'Unit Economics'!$G6)^0.25+D30,0) -> 42 | E44: =ROUND(D44*(1-'Unit Economics'!$G6)^0.25+E30,0) -> 83 | F44: =ROUND(E44*(1-'Unit Economics'!$G6)^0.25+F30,0) -> 150 | G44: =ROUND(F44*(1-'Unit Economics'!$G6)^0.25+G30,0) -> 238 | H44: =ROUND(G44*(1-'Unit Economics'!$G6)^0.25+H30,0) -> 359 | I44: =ROUND(H44*(1-'Unit Economics'!$G6)^0.25+I30,0) -> 513 | J44: =ROUND(I44*(1-'Unit Economics'!$G6)^0.25+J30,0) -> 696 | K44: =ROUND(J44*(1-'Unit Economics'!$G6)^0.25+K30,0) -> 873 | ... N44: =ROUND(M44*(1-'Unit Economics'!$G6)^0.25+N30,0) -> 1558
B45: Pharmacy / medical | C45: =C31 -> 4 | D45: =ROUND(C45*(1-'Unit Economics'!$G7)^0.25+D31,0) -> 11 | E45: =ROUND(D45*(1-'Unit Economics'!$G7)^0.25+E31,0) -> 22 | F45: =ROUND(E45*(1-'Unit Economics'!$G7)^0.25+F31,0) -> 39 | G45: =ROUND(F45*(1-'Unit Economics'!$G7)^0.25+G31,0) -> 86 | H45: =ROUND(G45*(1-'Unit Economics'!$G7)^0.25+H31,0) -> 150 | I45: =ROUND(H45*(1-'Unit Economics'!$G7)^0.25+I31,0) -> 231 | J45: =ROUND(I45*(1-'Unit Economics'!$G7)^0.25+J31,0) -> 330 | K45: =ROUND(J45*(1-'Unit Economics'!$G7)^0.25+K31,0) -> 454 | ... N45: =ROUND(M45*(1-'Unit Economics'!$G7)^0.25+N31,0) -> 935
B46: Auto parts / hardware | C46: =C32 -> 4 | D46: =ROUND(C46*(1-'Unit Economics'!$G8)^0.25+D32,0) -> 11 | E46: =ROUND(D46*(1-'Unit Economics'!$G8)^0.25+E32,0) -> 22 | F46: =ROUND(E46*(1-'Unit Economics'!$G8)^0.25+F32,0) -> 39 | G46: =ROUND(F46*(1-'Unit Economics'!$G8)^0.25+G32,0) -> 73 | H46: =ROUND(G46*(1-'Unit Economics'!$G8)^0.25+H32,0) -> 120 | I46: =ROUND(H46*(1-'Unit Economics'!$G8)^0.25+I32,0) -> 180 | J46: =ROUND(I46*(1-'Unit Economics'!$G8)^0.25+J32,0) -> 252 | K46: =ROUND(J46*(1-'Unit Economics'!$G8)^0.25+K32,0) -> 336 | ... N46: =ROUND(M46*(1-'Unit Economics'!$G8)^0.25+N32,0) -> 661
B47: Electronics / mobiles | C47: =C33 -> 0 | D47: =ROUND(C47*(1-'Unit Economics'!$G9)^0.25+D33,0) -> 0 | E47: =ROUND(D47*(1-'Unit Economics'!$G9)^0.25+E33,0) -> 0 | F47: =ROUND(E47*(1-'Unit Economics'!$G9)^0.25+F33,0) -> 0 | G47: =ROUND(F47*(1-'Unit Economics'!$G9)^0.25+G33,0) -> 19 | H47: =ROUND(G47*(1-'Unit Economics'!$G9)^0.25+H33,0) -> 45 | I47: =ROUND(H47*(1-'Unit Economics'!$G9)^0.25+I33,0) -> 78 | J47: =ROUND(I47*(1-'Unit Economics'!$G9)^0.25+J33,0) -> 116 | K47: =ROUND(J47*(1-'Unit Economics'!$G9)^0.25+K33,0) -> 177 | ... N47: =ROUND(M47*(1-'Unit Economics'!$G9)^0.25+N33,0) -> 406
...

Sheet Summary
B2: Three-Year Summary
B3: Both cases, side by side. Every figure recalculates from the Assumptions sheet and the two hiring plans.
C5: Base Case | F5: Aggressive Case
C6: Year 1 | D6: Year 2 | E6: Year 3 | F6: Year 1 | G6: Year 2 | H6: Year 3
B7: New shops signed | C7: =SUM('Base Case'!C12:F12) -> 96 | D7: =SUM('Base Case'!G12:J12) -> 240 | E7: =SUM('Base Case'!K12:N12) -> 432 | F7: =SUM('Aggressive Case'!C12:F12) -> 264 | G7: =SUM('Aggressive Case'!G12:J12) -> 1536 | H7: =SUM('Aggressive Case'!K12:N12) -> 3360 | J7: Gross additions in the year, before churn.
B8: Active shops at year end | C8: ='Base Case'!F55 -> 92 | D8: ='Base Case'!J55 -> 302 | E8: ='Base Case'!N55 -> 652 | F8: ='Aggressive Case'!F55 -> 252 | G8: ='Aggressive Case'!J55 -> 1654 | H8: ='Aggressive Case'!N55 -> 4501 | J8: After churn. This is the number that compounds.
B9: Subscription revenue | C9: =SUM('Base Case'!C58:F58) -> 356376 | D9: =SUM('Base Case'!G58:J58) -> 1516012 | E9: =SUM('Base Case'!K58:N58) -> 3559211.5 | F9: =SUM('Aggressive Case'!C58:F58) -> 868803.25 | G9: =SUM('Aggressive Case'!G58:J58) -> 7037760.8 | H9: =SUM('Aggressive Case'!K58:N58) -> 22247596 | J9: Recognised evenly across the year.
B10: Launch service revenue | C10: =SUM('Base Case'!C59:F59) -> 479904 | D10: =SUM('Base Case'!G59:J59) -> 1199760 | E10: =SUM('Base Case'!K59:N59) -> 2159568 | F10: =SUM('Aggressive Case'!C59:F59) -> 1319736 | G10: =SUM('Aggressive Case'!G59:J59) -> 7678464 | H10: =SUM('Aggressive Case'!K59:N59) -> 16796640 | J10: One-time ₹4,999 per new shop. Services, not SaaS.
B11: Total revenue | C11: =SUM('Base Case'!C60:F60) -> 836280 | D11: =SUM('Base Case'!G60:J60) -> 2715772 | E11: =SUM('Base Case'!K60:N60) -> 5718779.5 | F11: =SUM('Aggressive Case'!C60:F60) -> 2188539.2 | G11: =SUM('Aggressive Case'!G60:J60) -> 14716225 | H11: =SUM('Aggressive Case'!K60:N60) -> 39044236
B12: Service share of revenue | C12: =IF(SUM('Base Case'!C60:F60)=0,0,SUM('Base Case'!C59:F59)/SUM('Base Case'!C60:F60)) -> 0.57385565 | D12: =IF(SUM('Base Case'!G60:J60)=0,0,SUM('Base Case'!G59:J59)/SUM('Base Case'!G60:J60)) -> 0.44177494 | E12: =IF(SUM('Base Case'!K60:N60)=0,0,SUM('Base Case'!K59:N59)/SUM('Base Case'!K60:N60)) -> 0.37762743 | F12: =IF(SUM('Aggressive Case'!C60:F60)=0,0,SUM('Aggressive Case'!C59:F59)/SUM('Aggressive Case'!C60:F60)) -> 0.6030214 | G12: =IF(SUM('Aggressive Case'!G60:J60)=0,0,SUM('Aggressive Case'!G59:J59)/SUM('Aggressive Case'!G60:J60)) -> 0.5217686 | H12: =IF(SUM('Aggressive Case'!K60:N60)=0,0,SUM('Aggressive Case'!K59:N59)/SUM('Aggressive Case'!K60:N60)) -> 0.43019513 | J12: Keep this under ~30% or the business gets valued as a services firm.
B13: Exit ARR | C13: ='Base Case'!F61 -> 668608 | D13: ='Base Case'!J61 -> 2135548 | E13: ='Base Case'!N61 -> 4494398 | F13: ='Aggressive Case'!F61 -> 1798548 | G13: ='Aggressive Case'!J61 -> 11282546 | H13: ='Aggressive Case'!N61 -> 29923949 | J13: Active shops × blended annual price at year end. The number a buyer prices off.
B14: EBITDA | C14: =SUM('Base Case'!C68:F68) -> -897910.8 | D14: =SUM('Base Case'!G68:J68) -> -1085801.6 | E14: =SUM('Base Case'!K68:N68) -> -1875684.9 | F14: =SUM('Aggressive Case'!C68:F68) -> -2695166.2 | G14: =SUM('Aggressive Case'!G68:J68) -> -8937964 | H14: =SUM('Aggressive Case'!K68:N68) -> -12211910 | J14: Negative years are the investment; watch when it turns.
B15: Cumulative EBITDA | C15: ='Base Case'!F69 -> -897910.8 | D15: ='Base Case'!J69 -> -1983712.4 | E15: ='Base Case'!N69 -> -3859397.4 | F15: ='Aggressive Case'!F69 -> -2695166.2 | G15: ='Aggressive Case'!J69 -> -11633130 | H15: ='Aggressive Case'!N69 -> -23845041 | J15: The trough of this row is roughly the funding you need.
B16: Shops to cover fixed cost | C16: ='Base Case'!F70 -> 153 | D16: ='Base Case'!J70 -> 363 | E16: ='Base Case'!N70 -> 584 | F16: ='Aggressive Case'!F70 -> 791 | G16: ='Aggressive Case'!J70 -> 2047 | H16: ='Aggressive Case'!N70 -> 3804 | J16: Engineering + support ÷ contribution per shop. Sales is excluded — it is growth spend, not overhead. When active shops pass this line, the base pays for itself and every rep becomes optional.
B18: Revenue mix by trade at year 3 (active shops)
C19: Base | F19: Aggressive
B20: Restaurant / café | C20: ='Base Case'!N44 -> 290 | F20: ='Aggressive Case'!N44 -> 1558
B21: Pharmacy / medical | C21: ='Base Case'!N45 -> 130 | F21: ='Aggressive Case'!N45 -> 935
B22: Auto parts / hardware | C22: ='Base Case'!N46 -> 96 | F22: ='Aggressive Case'!N46 -> 661
B23: Electronics / mobiles | C23: ='Base Case'!N47 -> 43 | F23: ='Aggressive Case'!N47 -> 406
B24: Clothing / fashion | C24: ='Base Case'!N48 -> 37 | F24: ='Aggressive Case'!N48 -> 375
B25: Footwear | C25: ='Base Case'!N49 -> 13 | F25: ='Aggressive Case'!N49 -> 157
B26: Cosmetics / beauty | C26: ='Base Case'!N50 -> 8 | F26: ='Aggressive Case'!N50 -> 116
B27: Furniture / home | C27: ='Base Case'!N51 -> 8 | F27: ='Aggressive Case'!N51 -> 94
B28: Stationery / books | C28: ='Base Case'!N52 -> 0 | F28: ='Aggressive Case'!N52 -> 60
B29: Kirana / general store | C29: ='Base Case'!N53 -> 22 | F29: ='Aggressive Case'!N53 -> 133
B30: Other / custom retail | C30: ='Base Case'!N54 -> 5 | F30: ='Aggressive Case'!N54 -> 6
B31: Total | C31: =SUM(C20:C30) -> 652 | F31: =SUM(F20:F30) -> 4501
B33: Read the Cumulative EBITDA row as the funding requirement: its lowest point is roughly the cash you must have before the business pays for itself. In the base case that trough is small and self-fundable. In the aggressive case it is the size of the round you would need to raise.
